Workbook

Sheet Cover
A1: Lumen Analytics · SaaS Financial Model
B3: Model overview
B5: Purpose: Three-year driver-based model for Lumen Analytics, a fictional
B6: B2B SaaS analytics platform. Illustrates how input drivers (customer
B7: acquisition, retention, ACV, opex ratios) translate into ARR, revenue,
B8: and operating margin across Base / Upside / Downside scenarios.
B10: How to use:
B11: 1. Open the Assumptions tab.
B12: 2. Change the scenario toggle (cell C3) — pick Base, Upside, or Downside from the dropdown.
B13: 3. All downstream metrics on Revenue, P&L, and Summary recalculate.
B15: Sheets:
B16: • Summary — headline KPIs and SaaS health metrics
B17: • Assumptions — scenario table + quarterly driver vectors
... B26: Built by Jialei Wu. Data is entirely synthetic.

Sheet Summary
A1: Lumen Analytics · Executive Summary
B3: Scenario | C3: =Scenario&" case" -> Base case | D3: (toggle on Assumptions!C3)
A5: Headline KPIs
B6: Metric | C6: FY 2024 | D6: FY 2025 | E6: FY 2026 | F6: Δ FY25→FY26
B7: Ending ARR ($M) | C7: =Revenue!F19/1000 -> 5.5747717 | D7: =Revenue!J19/1000 -> 11.278243 | E7: =Revenue!N19/1000 -> 19.850968 | F7: =IFERROR(E7/D7-1,0) -> 0.76011177
B8: Recognized revenue ($M) | C8: =SUM(Revenue!C22:F22)/1000000 -> 3.695174 | D8: =SUM(Revenue!G22:J22)/1000000 -> 8.2420351 | E8: =SUM(Revenue!K22:N22)/1000000 -> 15.335363 | F8: =IFERROR(E8/D8-1,0) -> 0.86062816
B9: Gross margin | C9: =IFERROR(SUM('P&L'!C7:F7)/SUM('P&L'!C5:F5),0) -> 0.78 | D9: =IFERROR(SUM('P&L'!G7:J7)/SUM('P&L'!G5:J5),0) -> 0.78 | E9: =IFERROR(SUM('P&L'!K7:N7)/SUM('P&L'!K5:N5),0) -> 0.78 | F9: =E9-D9 -> 0
B10: Operating margin | C10: =IFERROR(SUM('P&L'!C13:F13)/SUM('P&L'!C5:F5),0) -> -0.097621119 | D10: =IFERROR(SUM('P&L'!G13:J13)/SUM('P&L'!G5:J5),0) -> -0.0048983866 | E10: =IFERROR(SUM('P&L'!K13:N13)/SUM('P&L'!K5:N5),0) -> 0.088669258 | F10: =E10-D10 -> 0.093567644
B11: Ending customers | C11: =Revenue!F10 -> 347.1193 | D11: =Revenue!J10 -> 625.55823 | E11: =Revenue!N10 -> 987.26605 | F11: =IFERROR(E11/D11-1,0) -> 0.57821607
B12: New customers added | C12: =SUM(Revenue!C8:F8) -> 215.06976 | D12: =SUM(Revenue!G8:J8) -> 315.14218 | E12: =SUM(Revenue!K8:N8) -> 423.96865 | F12: =IFERROR(E12/D12-1,0) -> 0.345325
A14: SaaS Health Metrics
B15: Metric | C15: Value | D15: Commentary
B16: Net dollar retention (annual) | C16: =Assumptions!$C$32 -> 1.15 | D16: Target ≥ 110% for healthy B2B SaaS
B17: Gross logo retention (annual) | C17: =Assumptions!$C$31 -> 0.92 | D17: Target ≥ 90% for mid-market
B18: Fully-loaded CAC | C18: =Assumptions!$C$42 -> 11500 | D18: S&M + onboarding per new logo
B19: Gross CAC payback (months) | C19: =IFERROR(Assumptions!$C$42/(Assumptions!C47*Assumptions!$C$33/12),0) -> 12.637363 | D19: CAC ÷ monthly gross profit per customer
B20: LTV (gross profit basis) | C20: =IFERROR(Assumptions!C47*Assumptions!$C$33/(1-Assumptions!$C$31),0) -> 136500 | D20: ACV × GM ÷ churn rate
B21: LTV : CAC | C21: =IFERROR((Assumptions!C47*Assumptions!$C$33/(1-Assumptions!$C$31))/Assumptions!$C$42,0) -> 11.869565 | D21: Target ≥ 3.0x
B22: Rule of 40 (FY26) | C22: =IFERROR((Revenue!N19/Revenue!K19-1)+IFERROR(SUM('P&L'!K13:N13)/SUM('P&L'!K5:N5),0),0) -> 0.59788609 | D22: ARR growth + operating margin; target ≥ 40%
B25: Illustrative model. Synthetic data for portfolio demonstration.
B26: Toggle scenario via the Base / Upside / Downside dropdown on Assumptions!C3 — all downstream metrics update.

Sheet Assumptions
A1: Lumen Analytics · Driver Assumptions
A3: Scenario | C3: Base
A5: Scenario table
C6: Base | D6: Upside | E6: Downside
A7: Starting customers | C7: 150 | D7: 150 | E7: 150
A8: New customers · Y1 quarterly growth | C8: 0.12 | D8: 0.15 | E8: 0.08
A9: New customers · Y2 quarterly growth | C9: 0.09 | D9: 0.12 | E9: 0.05
A10: New customers · Y3 quarterly growth | C10: 0.07 | D10: 0.09 | E10: 0.03
A11: Starting new customers / qtr | C11: 45 | D11: 50 | E11: 35
A12: Gross logo retention (annual) | C12: 0.92 | D12: 0.94 | E12: 0.88
A13: Net dollar retention (annual) | C13: 1.15 | D13: 1.25 | E13: 1.05
A14: Gross margin | C14: 0.78 | D14: 0.8 | E14: 0.75
A15: S&M as % of revenue · Y1 | C15: 0.48 | D15: 0.42 | E15: 0.55
A16: S&M as % of revenue · Y3 | C16: 0.34 | D16: 0.28 | E16: 0.42
A17: R&D as % of revenue · Y1 | C17: 0.3 | D17: 0.26 | E17: 0.34
A18: R&D as % of revenue · Y3 | C18: 0.22 | D18: 0.2 | E18: 0.26
... A23: Fully-loaded CAC ($) | C23: 11500 | D23: 10500 | E23: 13000
A25: Active (driven by scenario)
A26: Starting customers | C26: =INDEX(C7:E7,MATCH(Scenario,$C$6:$E$6,0)) -> 150
A27: New customers · Y1 quarterly growth | C27: =INDEX(C8:E8,MATCH(Scenario,$C$6:$E$6,0)) -> 0.12
A28: New customers · Y2 quarterly growth | C28: =INDEX(C9:E9,MATCH(Scenario,$C$6:$E$6,0)) -> 0.09
A29: New customers · Y3 quarterly growth | C29: =INDEX(C10:E10,MATCH(Scenario,$C$6:$E$6,0)) -> 0.07
A30: Starting new customers / qtr | C30: =INDEX(C11:E11,MATCH(Scenario,$C$6:$E$6,0)) -> 45
A31: Gross logo retention (annual) | C31: =INDEX(C12:E12,MATCH(Scenario,$C$6:$E$6,0)) -> 0.92
A32: Net dollar retention (annual) | C32: =INDEX(C13:E13,MATCH(Scenario,$C$6:$E$6,0)) -> 1.15
A33: Gross margin | C33: =INDEX(C14:E14,MATCH(Scenario,$C$6:$E$6,0)) -> 0.78
A34: S&M as % of revenue · Y1 | C34: =INDEX(C15:E15,MATCH(Scenario,$C$6:$E$6,0)) -> 0.48
A35: S&M as % of revenue · Y3 | C35: =INDEX(C16:E16,MATCH(Scenario,$C$6:$E$6,0)) -> 0.34
A36: R&D as % of revenue · Y1 | C36: =INDEX(C17:E17,MATCH(Scenario,$C$6:$E$6,0)) -> 0.3
A37: R&D as % of revenue · Y3 | C37: =INDEX(C18:E18,MATCH(Scenario,$C$6:$E$6,0)) -> 0.22
... A42: Fully-loaded CAC ($) | C42: =INDEX(C23:E23,MATCH(Scenario,$C$6:$E$6,0)) -> 11500
A44: Quarterly driver vectors
B45: Units | C45: Q1 2024 | D45: Q2 2024 | E45: Q3 2024 | F45: Q4 2024 | G45: Q1 2025 | H45: Q2 2025 | I45: Q3 2025 | J45: Q4 2025 | K45: Q1 2026 | L45: Q2 2026 | M45: Q3 2026 | N45: Q4 2026 | O45: Total / Avg
A46: New customers / quarter | B46: count | C46: =Assumptions!$C$30 -> 45 | D46: =C46*(1+Assumptions!$C$27) -> 50.4 | E46: =D46*(1+Assumptions!$C$27) -> 56.448 | F46: =E46*(1+Assumptions!$C$27) -> 63.22176 | G46: =F46*(1+Assumptions!$C$28) -> 68.911718 | H46: =G46*(1+Assumptions!$C$28) -> 75.113773 | I46: =H46*(1+Assumptions!$C$28) -> 81.874013 | J46: =I46*(1+Assumptions!$C$28) -> 89.242674 | K46: =J46*(1+Assumptions!$C$29) -> 95.489661 | L46: =K46*(1+Assumptions!$C$29) -> 102.17394 | M46: =L46*(1+Assumptions!$C$29) -> 109.32611 | N46: =M46*(1+Assumptions!$C$29) -> 116.97894 | O46: =SUM(C46:N46) -> 954.18059
A47: Blended ACV | B47: $/yr | C47: =Assumptions!$C$40*(1+Assumptions!$C$41)^0 -> 14000 | D47: =Assumptions!$C$40*(1+Assumptions!$C$41)^0 -> 14000 | E47: =Assumptions!$C$40*(1+Assumptions!$C$41)^0 -> 14000 | F47: =Assumptions!$C$40*(1+Assumptions!$C$41)^0 -> 14000 | G47: =Assumptions!$C$40*(1+Assumptions!$C$41)^1 -> 14700 | H47: =Assumptions!$C$40*(1+Assumptions!$C$41)^1 -> 14700 | I47: =Assumptions!$C$40*(1+Assumptions!$C$41)^1 -> 14700 | J47: =Assumptions!$C$40*(1+Assumptions!$C$41)^1 -> 14700 | K47: =Assumptions!$C$40*(1+Assumptions!$C$41)^2 -> 15435 | L47: =Assumptions!$C$40*(1+Assumptions!$C$41)^2 -> 15435 | M47: =Assumptions!$C$40*(1+Assumptions!$C$41)^2 -> 15435 | N47: =Assumptions!$C$40*(1+Assumptions!$C$41)^2 -> 15435 | O47: =AVERAGE(C47:N47) -> 14711.667
A48: Quarterly gross churn rate | B48: % | C48: =1-Assumptions!$C$31^(1/4) -> 0.020629639 | D48: =1-Assumptions!$C$31^(1/4) -> 0.020629639 | E48: =1-Assumptions!$C$31^(1/4) -> 0.020629639 | F48: =1-Assumptions!$C$31^(1/4) -> 0.020629639 | G48: =1-Assumptions!$C$31^(1/4) -> 0.020629639 | H48: =1-Assumptions!$C$31^(1/4) -> 0.020629639 | I48: =1-Assumptions!$C$31^(1/4) -> 0.020629639 | J48: =1-Assumptions!$C$31^(1/4) -> 0.020629639 | ... N48: =1-Assumptions!$C$31^(1/4) -> 0.020629639
A49: Quarterly net expansion rate | B49: % | C49: =Assumptions!$C$32^(1/4)-Assumptions!$C$31^(1/4) -> 0.056187715 | D49: =Assumptions!$C$32^(1/4)-Assumptions!$C$31^(1/4) -> 0.056187715 | E49: =Assumptions!$C$32^(1/4)-Assumptions!$C$31^(1/4) -> 0.056187715 | F49: =Assumptions!$C$32^(1/4)-Assumptions!$C$31^(1/4) -> 0.056187715 | G49: =Assumptions!$C$32^(1/4)-Assumptions!$C$31^(1/4) -> 0.056187715 | H49: =Assumptions!$C$32^(1/4)-Assumptions!$C$31^(1/4) -> 0.056187715 | I49: =Assumptions!$C$32^(1/4)-Assumptions!$C$31^(1/4) -> 0.056187715 | J49: =Assumptions!$C$32^(1/4)-Assumptions!$C$31^(1/4) -> 0.056187715 | ... N49: =Assumptions!$C$32^(1/4)-Assumptions!$C$31^(1/4) -> 0.056187715
A50: S&M · % of revenue | B50: % | C50: =Assumptions!$C$34+(Assumptions!$C$35-Assumptions!$C$34)*0/11 -> 0.48 | D50: =Assumptions!$C$34+(Assumptions!$C$35-Assumptions!$C$34)*1/11 -> 0.46727273 | E50: =Assumptions!$C$34+(Assumptions!$C$35-Assumptions!$C$34)*2/11 -> 0.45454545 | F50: =Assumptions!$C$34+(Assumptions!$C$35-Assumptions!$C$34)*3/11 -> 0.44181818 | G50: =Assumptions!$C$34+(Assumptions!$C$35-Assumptions!$C$34)*4/11 -> 0.42909091 | H50: =Assumptions!$C$34+(Assumptions!$C$35-Assumptions!$C$34)*5/11 -> 0.41636364 | I50: =Assumptions!$C$34+(Assumptions!$C$35-Assumptions!$C$34)*6/11 -> 0.40363636 | J50: =Assumptions!$C$34+(Assumptions!$C$35-Assumptions!$C$34)*7/11 -> 0.39090909 | K50: =Assumptions!$C$34+(Assumptions!$C$35-Assumptions!$C$34)*8/11 -> 0.37818182 | L50: =Assumptions!$C$34+(Assumptions!$C$35-Assumptions!$C$34)*9/11 -> 0.36545455 | M50: =Assumptions!$C$34+(Assumptions!$C$35-Assumptions!$C$34)*10/11 -> 0.35272727 | N50: =Assumptions!$C$34+(Assumptions!$C$35-Assumptions!$C$34)*11/11 -> 0.34
A51: R&D · % of revenue | B51: % | C51: =Assumptions!$C$36+(Assumptions!$C$37-Assumptions!$C$36)*0/11 -> 0.3 | D51: =Assumptions!$C$36+(Assumptions!$C$37-Assumptions!$C$36)*1/11 -> 0.29272727 | E51: =Assumptions!$C$36+(Assumptions!$C$37-Assumptions!$C$36)*2/11 -> 0.28545455 | F51: =Assumptions!$C$36+(Assumptions!$C$37-Assumptions!$C$36)*3/11 -> 0.27818182 | G51: =Assumptions!$C$36+(Assumptions!$C$37-Assumptions!$C$36)*4/11 -> 0.27090909 | H51: =Assumptions!$C$36+(Assumptions!$C$37-Assumptions!$C$36)*5/11 -> 0.26363636 | I51: =Assumptions!$C$36+(Assumptions!$C$37-Assumptions!$C$36)*6/11 -> 0.25636364 | J51: =Assumptions!$C$36+(Assumptions!$C$37-Assumptions!$C$36)*7/11 -> 0.24909091 | K51: =Assumptions!$C$36+(Assumptions!$C$37-Assumptions!$C$36)*8/11 -> 0.24181818 | L51: =Assumptions!$C$36+(Assumptions!$C$37-Assumptions!$C$36)*9/11 -> 0.23454545 | M51: =Assumptions!$C$36+(Assumptions!$C$37-Assumptions!$C$36)*10/11 -> 0.22727273 | N51: =Assumptions!$C$36+(Assumptions!$C$37-Assumptions!$C$36)*11/11 -> 0.22
A52: G&A · % of revenue | B52: % | C52: =Assumptions!$C$38+(Assumptions!$C$39-Assumptions!$C$38)*0/11 -> 0.14 | D52: =Assumptions!$C$38+(Assumptions!$C$39-Assumptions!$C$38)*1/11 -> 0.13636364 | E52: =Assumptions!$C$38+(Assumptions!$C$39-Assumptions!$C$38)*2/11 -> 0.13272727 | F52: =Assumptions!$C$38+(Assumptions!$C$39-Assumptions!$C$38)*3/11 -> 0.12909091 | G52: =Assumptions!$C$38+(Assumptions!$C$39-Assumptions!$C$38)*4/11 -> 0.12545455 | H52: =Assumptions!$C$38+(Assumptions!$C$39-Assumptions!$C$38)*5/11 -> 0.12181818 | I52: =Assumptions!$C$38+(Assumptions!$C$39-Assumptions!$C$38)*6/11 -> 0.11818182 | J52: =Assumptions!$C$38+(Assumptions!$C$39-Assumptions!$C$38)*7/11 -> 0.11454545 | K52: =Assumptions!$C$38+(Assumptions!$C$39-Assumptions!$C$38)*8/11 -> 0.11090909 | L52: =Assumptions!$C$38+(Assumptions!$C$39-Assumptions!$C$38)*9/11 -> 0.10727273 | M52: =Assumptions!$C$38+(Assumptions!$C$39-Assumptions!$C$38)*10/11 -> 0.10363636 | N52: =Assumptions!$C$38+(Assumptions!$C$39-Assumptions!$C$38)*11/11 -> 0.1
...

Sheet Revenue
A1: Lumen Analytics · Revenue Build
A3: All figures in actual $ unless marked otherwise.
A5: Customer Count
B6: Units | C6: Q1 2024 | D6: Q2 2024 | E6: Q3 2024 | F6: Q4 2024 | G6: Q1 2025 | H6: Q2 2025 | I6: Q3 2025 | J6: Q4 2025 | K6: Q1 2026 | L6: Q2 2026 | M6: Q3 2026 | N6: Q4 2026 | O6: Total / Avg
A7: Beginning customers | C7: =Assumptions!$C$26 -> 150 | D7: =C10 -> 191.90555 | E7: =D10 -> 238.34661 | F7: =E10 -> 289.87761 | G7: =F10 -> 347.1193 | H7: =G10 -> 408.87007 | I7: =H10 -> 475.549 | J7: =I10 -> 547.61261 | K7: =J10 -> 625.55823 | ... N7: =M10 -> 888.619
A8: + New customers | C8: =Assumptions!C46 -> 45 | D8: =Assumptions!D46 -> 50.4 | E8: =Assumptions!E46 -> 56.448 | F8: =Assumptions!F46 -> 63.22176 | G8: =Assumptions!G46 -> 68.911718 | H8: =Assumptions!H46 -> 75.113773 | I8: =Assumptions!I46 -> 81.874013 | J8: =Assumptions!J46 -> 89.242674 | ... N8: =Assumptions!N46 -> 116.97894 | O8: =SUM(C8:N8) -> 954.18059
A9: – Churned customers | C9: =-C7*Assumptions!C48 -> -3.0944458 | D9: =-D7*Assumptions!D48 -> -3.9589422 | E9: =-E7*Assumptions!E48 -> -4.9170045 | F9: =-F7*Assumptions!F48 -> -5.9800703 | G9: =-G7*Assumptions!G48 -> -7.1609457 | H9: =-H7*Assumptions!H48 -> -8.4348418 | I9: =-I7*Assumptions!I48 -> -9.8104041 | J9: =-J7*Assumptions!J48 -> -11.29705 | ... N9: =-N7*Assumptions!N48 -> -18.331889 | O9: =SUM(C9:N9) -> -116.91453
A10: Ending customers | C10: =C7+C8+C9 -> 191.90555 | D10: =D7+D8+D9 -> 238.34661 | E10: =E7+E8+E9 -> 289.87761 | F10: =F7+F8+F9 -> 347.1193 | G10: =G7+G8+G9 -> 408.87007 | H10: =H7+H8+H9 -> 475.549 | I10: =I7+I8+I9 -> 547.61261 | J10: =J7+J8+J9 -> 625.55823 | ... N10: =N7+N8+N9 -> 987.26605 | O10: =N10 -> 987.26605
A13: ARR Waterfall ($K)
B14: Units | C14: Q1 2024 | D14: Q2 2024 | E14: Q3 2024 | F14: Q4 2024 | G14: Q1 2025 | H14: Q2 2025 | I14: Q3 2025 | J14: Q4 2025 | K14: Q1 2026 | L14: Q2 2026 | M14: Q3 2026 | N14: Q4 2026 | O14: Total / Avg
A15: Beginning ARR | C15: =Assumptions!$C$26*Assumptions!C47/1000 -> 2100 | D15: =C19 -> 2804.672 | E15: =D19 -> 3610.0007 | F15: =E19 -> 4528.6374 | G15: =F19 -> 5574.7717 | H15: =G19 -> 6786.0021 | I15: =H19 -> 8131.4717 | J15: =I19 -> 9624.1592 | K15: =J19 -> 11278.243 | ... N15: =M19 -> 17425.772
A16: + New ARR | C16: =Revenue!C8*Assumptions!C47/1000 -> 630 | D16: =Revenue!D8*Assumptions!D47/1000 -> 705.6 | E16: =Revenue!E8*Assumptions!E47/1000 -> 790.272 | F16: =Revenue!F8*Assumptions!F47/1000 -> 885.10464 | G16: =Revenue!G8*Assumptions!G47/1000 -> 1013.0023 | H16: =Revenue!H8*Assumptions!H47/1000 -> 1104.1725 | I16: =Revenue!I8*Assumptions!I47/1000 -> 1203.548 | J16: =Revenue!J8*Assumptions!J47/1000 -> 1311.8673 | ... N16: =Revenue!N8*Assumptions!N47/1000 -> 1805.5699 | O16: =SUM(C16:N16) -> 14187.523
A17: + Expansion / upsell ARR | C17: =C15*Assumptions!C49 -> 117.9942 | D17: =D15*Assumptions!D49 -> 157.58811 | E17: =E15*Assumptions!E49 -> 202.83769 | F17: =F15*Assumptions!F49 -> 254.45379 | G17: =G15*Assumptions!G49 -> 313.23368 | H17: =H15*Assumptions!H49 -> 381.28995 | I17: =I15*Assumptions!I49 -> 456.88882 | J17: =J15*Assumptions!J49 -> 540.75951 | ... N17: =N15*Assumptions!N49 -> 979.11428 | O17: =SUM(C17:N17) -> 5630.8407
A18: – Churned ARR | C18: =-C15*Assumptions!C48 -> -43.322241 | D18: =-D15*Assumptions!D48 -> -57.859369 | E18: =-E15*Assumptions!E48 -> -74.47301 | F18: =-F15*Assumptions!F48 -> -93.424153 | G18: =-G15*Assumptions!G48 -> -115.00552 | H18: =-H15*Assumptions!H48 -> -139.99277 | I18: =-I15*Assumptions!I48 -> -167.74932 | J18: =-J15*Assumptions!J48 -> -198.54293 | ... N18: =-N15*Assumptions!N48 -> -359.48737 | O18: =SUM(C18:N18) -> -2067.3952
A19: Ending ARR | C19: =C15+C16+C17+C18 -> 2804.672 | D19: =D15+D16+D17+D18 -> 3610.0007 | E19: =E15+E16+E17+E18 -> 4528.6374 | F19: =F15+F16+F17+F18 -> 5574.7717 | G19: =G15+G16+G17+G18 -> 6786.0021 | H19: =H15+H16+H17+H18 -> 8131.4717 | I19: =I15+I16+I17+I18 -> 9624.1592 | J19: =J15+J16+J17+J18 -> 11278.243 | ... N19: =N15+N16+N17+N18 -> 19850.968 | O19: =N19 -> 19850.968
A20: Ending MRR | C20: =C19/12 -> 233.72266 | D20: =D19/12 -> 300.83339 | E20: =E19/12 -> 377.38645 | F20: =F19/12 -> 464.5643 | G20: =G19/12 -> 565.50017 | H20: =H19/12 -> 677.62264 | I20: =I19/12 -> 802.01327 | J20: =J19/12 -> 939.85359 | ... N20: =N19/12 -> 1654.2474
A21: Recognized revenue | C21: =AVERAGE(C15,C19)/4 -> 613.084 | D21: =AVERAGE(D15,D19)/4 -> 801.83408 | E21: =AVERAGE(E15,E19)/4 -> 1017.3298 | F21: =AVERAGE(F15,F19)/4 -> 1262.9261 | G21: =AVERAGE(G15,G19)/4 -> 1545.0967 | H21: =AVERAGE(H15,H19)/4 -> 1864.6842 | I21: =AVERAGE(I15,I19)/4 -> 2219.4539 | J21: =AVERAGE(J15,J19)/4 -> 2612.8003 | ... N21: =AVERAGE(N15,N19)/4 -> 4659.5925 | O21: =SUM(C21:N21) -> 27272.572
A22: · in dollars (for P&L) | C22: =C21*1000 -> 613084 | D22: =D21*1000 -> 801834.08 | E22: =E21*1000 -> 1017329.8 | F22: =F21*1000 -> 1262926.1 | G22: =G21*1000 -> 1545096.7 | H22: =H21*1000 -> 1864684.2 | I22: =I21*1000 -> 2219453.9 | J22: =J21*1000 -> 2612800.3 | ... N22: =N21*1000 -> 4659592.5 | O22: =SUM(C22:N22) -> 27272572

Sheet P&L
A1: Lumen Analytics · Income Statement (Quarterly)
A3: Income Statement ($)
B4: Units | C4: Q1 2024 | D4: Q2 2024 | E4: Q3 2024 | F4: Q4 2024 | G4: Q1 2025 | H4: Q2 2025 | I4: Q3 2025 | J4: Q4 2025 | K4: Q1 2026 | L4: Q2 2026 | M4: Q3 2026 | N4: Q4 2026 | O4: Total / Avg
A5: Revenue | C5: =Revenue!C22 -> 613084 | D5: =Revenue!D22 -> 801834.08 | E5: =Revenue!E22 -> 1017329.8 | F5: =Revenue!F22 -> 1262926.1 | G5: =Revenue!G22 -> 1545096.7 | H5: =Revenue!H22 -> 1864684.2 | I5: =Revenue!I22 -> 2219453.9 | J5: =Revenue!J22 -> 2612800.3 | ... N5: =Revenue!N22 -> 4659592.5 | O5: =SUM(C5:N5) -> 27272572
A6: Cost of revenue | C6: =-C5*(1-Assumptions!$C$33) -> -134878.48 | D6: =-D5*(1-Assumptions!$C$33) -> -176403.5 | E6: =-E5*(1-Assumptions!$C$33) -> -223812.55 | F6: =-F5*(1-Assumptions!$C$33) -> -277843.75 | G6: =-G5*(1-Assumptions!$C$33) -> -339921.28 | H6: =-H5*(1-Assumptions!$C$33) -> -410230.53 | I6: =-I5*(1-Assumptions!$C$33) -> -488279.85 | J6: =-J5*(1-Assumptions!$C$33) -> -574816.06 | ... N6: =-N5*(1-Assumptions!$C$33) -> -1025110.3 | O6: =SUM(C6:N6) -> -5999965.8
A7: Gross profit | C7: =C5+C6 -> 478205.52 | D7: =D5+D6 -> 625430.58 | E7: =E5+E6 -> 793517.21 | F7: =F5+F6 -> 985082.38 | G7: =G5+G6 -> 1205175.4 | H7: =H5+H6 -> 1454453.7 | I7: =I5+I6 -> 1731174 | J7: =J5+J6 -> 2037984.2 | ... N7: =N5+N6 -> 3634482.1 | O7: =SUM(C7:N7) -> 21272606
A8: Gross margin | C8: =IFERROR(C7/C5,0) -> 0.78 | D8: =IFERROR(D7/D5,0) -> 0.78 | E8: =IFERROR(E7/E5,0) -> 0.78 | F8: =IFERROR(F7/F5,0) -> 0.78 | G8: =IFERROR(G7/G5,0) -> 0.78 | H8: =IFERROR(H7/H5,0) -> 0.78 | I8: =IFERROR(I7/I5,0) -> 0.78 | J8: =IFERROR(J7/J5,0) -> 0.78 | ... O8: =IFERROR(O7/O5,0) -> 0.78
A9: Sales & marketing | C9: =-C5*Assumptions!C50 -> -294280.32 | D9: =-D5*Assumptions!D50 -> -374675.2 | E9: =-E5*Assumptions!E50 -> -462422.62 | F9: =-F5*Assumptions!F50 -> -557983.73 | G9: =-G5*Assumptions!G50 -> -662986.95 | H9: =-H5*Assumptions!H50 -> -776386.7 | I9: =-I5*Assumptions!I50 -> -895852.29 | J9: =-J5*Assumptions!J50 -> -1021367.4 | ... N9: =-N5*Assumptions!N50 -> -1584261.4 | O9: =SUM(C9:N9) -> -10518692
A10: Research & development | C10: =-C5*Assumptions!C51 -> -183925.2 | D10: =-D5*Assumptions!D51 -> -234718.7 | E10: =-E5*Assumptions!E51 -> -290401.4 | F10: =-F5*Assumptions!F51 -> -351323.09 | G10: =-G5*Assumptions!G51 -> -418580.75 | H10: =-H5*Assumptions!H51 -> -491598.57 | I10: =-I5*Assumptions!I51 -> -568987.26 | J10: =-J5*Assumptions!J51 -> -650824.8 | ... N10: =-N5*Assumptions!N51 -> -1025110.3 | O10: =SUM(C10:N10) -> -6711975.9
A11: General & administrative | C11: =-C5*Assumptions!C52 -> -85831.759 | D11: =-D5*Assumptions!D52 -> -109341.01 | E11: =-E5*Assumptions!E52 -> -135027.4 | F11: =-F5*Assumptions!F52 -> -163032.28 | G11: =-G5*Assumptions!G52 -> -193839.41 | H11: =-H5*Assumptions!H52 -> -227152.44 | I11: =-I5*Assumptions!I52 -> -262299.09 | J11: =-J5*Assumptions!J52 -> -299284.4 | ... N11: =-N5*Assumptions!N52 -> -465959.25 | O11: =SUM(C11:N11) -> -3083262.2
A12: Total operating expenses | C12: =SUM(C9:C11) -> -564037.28 | D12: =SUM(D9:D11) -> -718734.91 | E12: =SUM(E9:E11) -> -887851.43 | F12: =SUM(F9:F11) -> -1072339.1 | G12: =SUM(G9:G11) -> -1275407.1 | H12: =SUM(H9:H11) -> -1495137.7 | I12: =SUM(I9:I11) -> -1727138.6 | J12: =SUM(J9:J11) -> -1971476.6 | ... N12: =SUM(N9:N11) -> -3075331 | O12: =SUM(C12:N12) -> -20313930
A13: Operating income | C13: =C7+C12 -> -85831.759 | D13: =D7+D12 -> -93304.33 | E13: =E7+E12 -> -94334.214 | F13: =F7+F12 -> -87256.714 | G13: =G7+G12 -> -70231.669 | H13: =H7+H12 -> -40684.019 | I13: =I7+I12 -> 4035.3707 | J13: =J7+J12 -> 66507.644 | ... N13: =N7+N12 -> 559151.1 | O13: =SUM(C13:N13) -> 958675.52
A14: Operating margin | C14: =IFERROR(C13/C5,0) -> -0.14 | D14: =IFERROR(D13/D5,0) -> -0.11636364 | E14: =IFERROR(E13/E5,0) -> -0.092727273 | F14: =IFERROR(F13/F5,0) -> -0.069090909 | G14: =IFERROR(G13/G5,0) -> -0.045454545 | H14: =IFERROR(H13/H5,0) -> -0.021818182 | I14: =IFERROR(I13/I5,0) -> 0.0018181818 | J14: =IFERROR(J13/J5,0) -> 0.025454545 | ... O14: =IFERROR(O13/O5,0) -> 0.035151637
A17: Annual Summary ($M)
B18: Units | C18: 2024 | D18: 2025 | E18: 2026
A19: Revenue | C19: =SUM(C5:F5)/1000 -> 3695.174 | D19: =SUM(G5:J5)/1000 -> 8242.0351 | E19: =SUM(K5:N5)/1000 -> 15335.363
A20: Gross profit | C20: =SUM(C7:F7)/1000 -> 2882.2357 | D20: =SUM(G7:J7)/1000 -> 6428.7874 | E20: =SUM(K7:N7)/1000 -> 11961.583
A21: Operating income | C21: =SUM(C13:F13)/1000 -> -360.72702 | D21: =SUM(G13:J13)/1000 -> -40.372674 | E21: =SUM(K13:N13)/1000 -> 1359.7752
A22: Gross margin | C22: =IFERROR(SUM(C7:F7)/SUM(C5:F5),0) -> 0.78 | D22: =IFERROR(SUM(G7:J7)/SUM(G5:J5),0) -> 0.78 | E22: =IFERROR(SUM(K7:N7)/SUM(K5:N5),0) -> 0.78
A23: Operating margin | C23: =IFERROR(SUM(C13:F13)/SUM(C5:F5),0) -> -0.097621119 | D23: =IFERROR(SUM(G13:J13)/SUM(G5:J5),0) -> -0.0048983866 | E23: =IFERROR(SUM(K13:N13)/SUM(K5:N5),0) -> 0.088669258
